<?xml version="1.0"?>
<robot xmlns:xacro="http://www.ros.org/wiki/xacro" >

    <xacro:include filename="inertial_macros.xacro"/> 

    <material name="white">
        <color rgba="1 1 1 1"/>
    </material>

    <material name="black">
        <color rgba="0 0 0 1"/>
    </material>

    <material name="red">
        <color rgba="1 0 0 1"/>
    </material>

    <material name="green">
        <color rgba="0 1 0 1"/>
    </material>

    <material name="blue">
        <color rgba="0 0 1 1"/>
    </material>

    <!-- BASE_FOOTPRINT LINK -->
    <joint name="base_footprint_joint" type="fixed">
        <parent link="base_link"/>
        <child link="base_footprint"/>
        <origin xyz="0 0 0" rpy="0 0 0"/>
    </joint>

    <link name="base_footprint">
    </link>

    <!-- LEFT WHEEL LINK -->

    <joint name="left_wheel_joint" type="continuous">
        <parent link="body_link"/>
        <child link="left_wheel"/>
        <origin xyz="0.075 0.1175 -.01" rpy="-${pi/2} 0 0" />
        <axis xyz="0 0 1"/>
    </joint>

    <link name="left_wheel">
        <visual>
            <geometry>
                <cylinder radius="0.018" length="0.03"/>
            </geometry>
            <material name="red"/>
        </visual>
        <collision>
            <geometry>
                <cylinder radius="0.018" length="0.03"/>
            </geometry>
        </collision>
        <xacro:inertial_cylinder mass="0.1" length="0.03" radius="0.018">
            <origin xyz="0 0 0" rpy="0 0 0"/>
        </xacro:inertial_cylinder>
    </link>

    <gazebo reference="left_wheel">
        <material>Gazebo/Red</material>
    </gazebo>

    <!-- RIGHT WHEEL LINK -->

    <joint name="right_wheel_joint" type="continuous">
        <parent link="body_link"/>
        <child link="right_wheel"/>
        <origin xyz="0.075 -0.1175 -.01" rpy="${pi/2} 0 0" />
        <axis xyz="0 0 -1"/>
    </joint>

    <link name="right_wheel">
        <visual>
            <geometry>
                <cylinder radius="0.018" length="0.03"/>
            </geometry>
            <material name="red"/>
        </visual>
        <collision>
            <geometry>
                <cylinder radius="0.018" length="0.03"/>
            </geometry>
        </collision>
        <xacro:inertial_cylinder mass="0.1" length="0.03" radius="0.018">
            <origin xyz="0 0 0" rpy="0 0 0"/>
        </xacro:inertial_cylinder>
    </link>

    <gazebo reference="right_wheel">
        <material>Gazebo/Red</material>
    </gazebo>

    <!-- FRONT CASTER WHEEL LINK -->

    <joint name="front_caster_wheel_joint" type="fixed">
        <parent link="body_link"/>
        <child link="front_caster_wheel"/>
        <origin xyz=".21 0.0 -0.01"/>
    </joint>
    
    <link name="front_caster_wheel">
        <visual>
            <geometry>
                <sphere radius="0.018"/>
            </geometry>
            <material name="red"/>
        </visual>
        <collision>
            <geometry>
                <sphere radius="0.018"/>
            </geometry>
        </collision>
        <xacro:inertial_sphere mass="0.1" radius="0.018">
            <origin xyz="0 0 0" rpy="0 0 0"/>
        </xacro:inertial_sphere>
    </link>

    <gazebo reference="front_caster_wheel">
        <material>Gazebo/Red</material>
        <mu1 value=".001"/>
        <mu2 value=".001"/>
    </gazebo>

    <!-- REAR CASTER WHEEL LINK -->

    <joint name="rear_caster_wheel_joint" type="fixed">
        <parent link="body_link"/>
        <child link="rear_caster_wheel"/>
        <origin xyz="0.0 0.0 -0.01"/>
    </joint>
    
    <link name="rear_caster_wheel">
        <visual>
            <geometry>
                <sphere radius="0.018"/>
            </geometry>
            <material name="red"/>
        </visual>
        <collision>
            <geometry>
                <sphere radius="0.018"/>
            </geometry>
        </collision>
        <xacro:inertial_sphere mass="0.1" radius="0.018">
            <origin xyz="0 0 0" rpy="0 0 0"/>
        </xacro:inertial_sphere>
    </link>

    <gazebo reference="rear_caster_wheel">
        <material>Gazebo/Red</material>
        <mu1 value=".001"/>
        <mu2 value=".001"/>
    </gazebo>

</robot>