<?xml version="1.0" encoding="utf-8"?>
<!-- This URDF was automatically created by SolidWorks to URDF Exporter! Originally created by Stephen Brawner (brawner@gmail.com) 
     Commit Version: 1.6.0-4-g7f85cfe  Build Version: 1.6.7995.38578
     For more information, please see http://wiki.ros.org/sw_urdf_exporter -->
<robot xmlns:xacro="http://ros.org/wiki/xacro"
  name="wilson">

  <link name = "base_link">
  </link>

  <link
    name="body_link">
    <inertial>
      <origin
        xyz="0.07097 -0.00089885 0.11258"
        rpy="0 0 0" />
      <mass
        value="3" />
      <inertia
        ixx="0.017986"
        ixy="0.0006756"
        ixz="0.00083241"
        iyy="0.020129"
        iyz="-8.9186E-05"
        izz="0.026466" />

    </inertial>
    <visual>
      <origin
        xyz="0 0 0"
        rpy="0 0 0" />
      <geometry>
        <mesh
          filename="package://wilson/meshes/body_link.STL" />
      </geometry>
      <material
        name="">
        <color
          rgba="0.3 0.3 0.3 1" />
      </material>
    </visual>
    <collision>
      <origin
        xyz="0 0 0"
        rpy="0 0 0" />
      <geometry>
        <mesh
          filename="package://wilson/collision_meshes/body_link.STL" />
      </geometry>
    </collision>
  </link>
  <joint
    name="body_joint"
    type="fixed">
    <origin
      xyz="0 0 0"
      rpy="0 0 0" />
    <parent
      link="base_link" />
    <child
      link="body_link" />
    <axis
      xyz="0 0 0" />
  </joint>
  <link
    name="laser_frame">
    <inertial>
      <origin
        xyz="-2.1176E-07 -4.0923E-05 -0.011888"
        rpy="0 0 0" />
      <mass
        value="0.001" />
      <inertia
        ixx="5.4479E-06"
        ixy="9.7064E-14"
        ixz="5.3555E-11"
        iyy="5.5226E-06"
        iyz="8.257E-09"
        izz="9.1788E-06" />
    </inertial>
    <visual>
      <origin
        xyz="0 0 0"
        rpy="0 0 0" />
      <geometry>
        <mesh
          filename="package://wilson/meshes/laser_frame.STL" />
      </geometry>
      <material
        name="">
        <color
          rgba="0.3 0.3 0.3 1" />
      </material>
    </visual>
    <collision>
      <origin
        xyz="0 0 0"
        rpy="0 0 0" />
      <geometry>
        <mesh
          filename="package://wilson/collision_meshes/laser_frame.STL" />
      </geometry>
    </collision>
  </link>
  <joint
    name="laser_joint"
    type="fixed">
    <origin
      xyz="0.028815 0.00026069 0.30272"
      rpy="0 0 0" />
    <parent
      link="body_link" />
    <child
      link="laser_frame" />
    <axis
      xyz="0 0 0" />
  </joint>
  <link
    name="camera_link">
    <inertial>
      <origin
        xyz="-0.017796 0 -5.5511E-17"
        rpy="0 0 0" />
      <mass
        value="0.0084406" />
      <inertia
        ixx="8.8741E-07"
        ixy="1.319E-22"
        ixz="-5.0892E-22"
        iyy="1.1543E-06"
        iyz="-2.074E-22"
        izz="1.1543E-06" />
    </inertial>
    <visual>
      <origin
        xyz="0 0 0"
        rpy="0 0 0" />
      <geometry>
        <mesh
          filename="package://wilson/meshes/camera_link.STL" />
      </geometry>
      <material
        name="">
        <color
          rgba="0.3 0.3 0.3 1" />
      </material>
    </visual>
    <collision>
      <origin
        xyz="0 0 0"
        rpy="0 0 0" />
      <geometry>
        <mesh
          filename="package://wilson/collision_meshes/camera_link.STL" />
      </geometry>
    </collision>
  </link>
  <joint
    name="camera_joint"
    type="fixed">
    <origin
      xyz="0.10065 0.00016353 0.24572"
      rpy="0 0 0" />
    <parent
      link="body_link" />
    <child
      link="camera_link" />
    <axis
      xyz="0 0 0" />
  </joint>
  <link
    name="depth_camera_link">
    <inertial>
      <origin
        xyz="-0.0035178 2.6724E-05 0"
        rpy="0 0 0" />
      <mass
        value="0.0035923" />
      <inertia
        ixx="7.2887E-07"
        ixy="-2.8971E-10"
        ixz="-3.3403E-23"
        iyy="3.6036E-07"
        iyz="-3.7283E-23"
        izz="3.7832E-07" />
    </inertial>
    <visual>
      <origin
        xyz="0 0 0"
        rpy="0 0 0" />
      <geometry>
        <mesh
          filename="package://wilson/meshes/depth_camera_link.STL" />
      </geometry>
      <material
        name="">
        <color
          rgba="0.3 0.3 0.3 1" />
      </material>
    </visual>
    <collision>
      <origin
        xyz="0 0 0"
        rpy="0 0 0" />
      <geometry>
        <mesh
          filename="package://wilson/collision_meshes/depth_camera_link.STL" />
      </geometry>
    </collision>
  </link>
  <joint
    name="depth_camera_joint"
    type="fixed">
    <origin
      xyz="0.07765 0.038164 0.24572"
      rpy="0 0 0" />
    <parent
      link="body_link" />
    <child
      link="depth_camera_link" />
    <axis
      xyz="0 0 0" />
  </joint>
  <link
    name="link_1">
    <inertial>
      <origin
        xyz="0 0 0"
        rpy="0 0 0" />
      <mass
        value="0.001" />
      <inertia
        ixx="0.001"
        ixy="0.001"
        ixz="0.001"
        iyy="0.001"
        iyz="0.001"
        izz="0.001" />
    </inertial>
    <visual>
      <origin
        xyz="0 0 0"
        rpy="0 0 0" />
      <geometry>
        <mesh
          filename="package://wilson/meshes/link_1.STL" />
      </geometry>
      <material
        name="">
        <color
          rgba="0.3 0.3 0.3 1" />
      </material>
    </visual>
    <collision>
      <origin
        xyz="0 0 0"
        rpy="0 0 0" />
      <geometry>
        <mesh
          filename="package://wilson/collision_meshes/link_1.STL" />
      </geometry>
    </collision>
  </link>
  <joint
    name="joint_1"
    type="revolute">
    <origin
      xyz="0.20284 -0.0445 0.055968"
      rpy="0 0 0" />
    <parent
      link="body_link" />
    <child
      link="link_1" />
    <axis
      xyz="0 0 1" />
    <limit
      lower="-1.5708"
      upper="1.3090"
      effort="100"
      velocity="1.0" />
  </joint>
  <link
    name="link_2">
    <inertial>
      <origin
        xyz="0.052 1.1102E-16 -4.8862E-05"
        rpy="0 0 0" />
      <mass
        value="0.001" />
      <inertia
        ixx="1.8027E-05"
        ixy="-5.0835E-12"
        ixz="-3.4406E-22"
        iyy="2.6081E-05"
        iyz="7.6203E-20"
        izz="1.3913E-05" />
    </inertial>
    <visual>
      <origin
        xyz="0 0 0"
        rpy="0 0 0" />
      <geometry>
        <mesh
          filename="package://wilson/meshes/link_2.STL" />
      </geometry>
      <material
        name="">
        <color
          rgba="0.3 0.3 0.3 1" />
      </material>
    </visual>
    <collision>
      <origin
        xyz="0 0 0"
        rpy="0 0 0" />
      <geometry>
        <mesh
          filename="package://wilson/collision_meshes/link_2.STL" />
      </geometry>
    </collision>
  </link>
  <joint
    name="joint_2"
    type="revolute">
    <origin
      xyz="0 -0.0002 0.041"
      rpy="1.5708 -1.5708 0" />
    <parent
      link="link_1" />
    <child
      link="link_2" />
    <axis
      xyz="0 0 1" />
    <limit
      lower="-1.7453"
      upper="1.7453"
      effort="100"
      velocity="1.0" />
  </joint>
  <link
    name="link_3">
    <inertial>
      <origin
        xyz="0.048456 4.4264E-09 0.00016422"
        rpy="0 0 0" />
      <mass
        value="0.001" />
      <inertia
        ixx="1.0479E-05"
        ixy="-2.5418E-12"
        ixz="5.8294E-08"
        iyy="1.4519E-05"
        iyz="-7.3801E-13"
        izz="6.8191E-06" />
    </inertial>
    <visual>
      <origin
        xyz="0 0 0"
        rpy="0 0 0" />
      <geometry>
        <mesh
          filename="package://wilson/meshes/link_3.STL" />
      </geometry>
      <material
        name="">
        <color
          rgba="0.3 0.3 0.3 1" />
      </material>
    </visual>
    <collision>
      <origin
        xyz="0 0 0"
        rpy="0 0 0" />
      <geometry>
        <mesh
          filename="package://wilson/collision_meshes/link_3.STL" />
      </geometry>
    </collision>
  </link>
  <joint
    name="joint_3"
    type="revolute">
    <origin
      xyz="0.10355 0 0.00025"
      rpy="0 0 0" />
    <parent
      link="link_2" />
    <child
      link="link_3" />
    <axis
      xyz="0 0 1" />
    <limit
      lower="-2.1817"
      upper="2.1817"
      effort="100"
      velocity="1.0" />
  </joint>
  <link
    name="link_4">
    <inertial>
      <origin
        xyz="0.051407 -1.2493E-05 0.00067072"
        rpy="0 0 0" />
      <mass
        value="0.0001" />
      <inertia
        ixx="5.9516E-05"
        ixy="-1.66E-10"
        ixz="2.2283E-06"
        iyy="7.3946E-05"
        iyz="-1.2305E-09"
        izz="2.67E-05" />
    </inertial>
    <visual>
      <origin
        xyz="0 0 0"
        rpy="0 0 0" />
      <geometry>
        <mesh
          filename="package://wilson/meshes/link_4.STL" />
      </geometry>
      <material
        name="">
        <color
          rgba="0.3 0.3 0.3 1" />
      </material>
    </visual>
    <collision>
      <origin
        xyz="0 0 0"
        rpy="0 0 0" />
      <geometry>
        <mesh
          filename="package://wilson/collision_meshes/link_4.STL" />
      </geometry>
    </collision>
  </link>
  <joint
    name="joint_4"
    type="revolute">
    <origin
      xyz="0.0639 0 0.0005"
      rpy="0 0 0" />
    <parent
      link="link_3" />
    <child
      link="link_4" />
    <axis
      xyz="0 0 1" />
    <limit
      lower="-2.0944"
      upper="2.0944"
      effort="100"
      velocity="1.0" />
  </joint>
  <link
    name="gripper_base">
    <inertial>
      <origin
        xyz="0.010715 1.0389E-05 1.8295E-05"
        rpy="0 0 0" />
      <mass
        value="0.001" />
      <inertia
        ixx="0.00012973"
        ixy="-6.8552E-09"
        ixz="-8.4335E-10"
        iyy="9.4298E-05"
        iyz="9.6632E-09"
        izz="4.7314E-05" />
    </inertial>
    <visual>
      <origin
        xyz="0 0 0"
        rpy="0 0 0" />
      <geometry>
        <mesh
          filename="package://wilson/meshes/gripper_base.STL" />
      </geometry>
      <material
        name="">
        <color
          rgba="0.3 0.3 0.3 1" />
      </material>
    </visual>
    <collision>
      <origin
        xyz="0 0 0"
        rpy="0 0 0" />
      <geometry>
        <mesh
          filename="package://wilson/collision_meshes/gripper_base.STL" />
      </geometry>
    </collision>
  </link>
  <joint
    name="gripper_base_joint"
    type="fixed">
    <origin
      xyz="0.077347 -0.00023665 0.00025"
      rpy="0 0 0" />
    <parent
      link="link_4" />
    <child
      link="gripper_base" />
    <axis
      xyz="0 0 0" />
  </joint>
  <link
    name="gripper_left_finger">
    <inertial>
      <origin
        xyz="0.013473 0.0020475 0.001721"
        rpy="0 0 0" />
      <mass
        value="0.001" />
      <inertia
        ixx="6.2762E-06"
        ixy="5.3005E-07"
        ixz="-5.6448E-07"
        iyy="4.6087E-06"
        iyz="9.4001E-07"
        izz="6.0257E-06" />
    </inertial>
    <visual>
      <origin
        xyz="0 0 0"
        rpy="0 0 0" />
      <geometry>
        <mesh
          filename="package://wilson/meshes/gripper_left_finger.STL" />
      </geometry>
      <material
        name="">
        <color
          rgba="0.3 0.3 0.3 1" />
      </material>
    </visual>
    <collision>
      <origin
        xyz="0 0 0"
        rpy="0 0 0" />
      <geometry>
        <mesh
          filename="package://wilson/collision_meshes/gripper_left_finger.STL" />
      </geometry>
    </collision>
  </link>
  <joint
    name="gripper_left_finger_joint"
    type="prismatic">
    <origin
      xyz="0.0272 0 0"
      rpy="0 0 0" />
    <parent
      link="gripper_base" />
    <child
      link="gripper_left_finger" />
    <axis
      xyz="0 0 1" />
    <limit
      lower="-0.001"
      upper="0.05"
      effort="0"
      velocity="0" />
  </joint>
  <link
    name="gripper_right_finger">
    <inertial>
      <origin
        xyz="0.013473 -0.0020475 -0.001721"
        rpy="0 0 0" />
      <mass
        value="0.001" />
      <inertia
        ixx="6.2762E-06"
        ixy="-5.3005E-07"
        ixz="5.6448E-07"
        iyy="4.6087E-06"
        iyz="9.4001E-07"
        izz="6.0257E-06" />
    </inertial>
    <visual>
      <origin
        xyz="0 0 0"
        rpy="0 0 0" />
      <geometry>
        <mesh
          filename="package://wilson/meshes/gripper_right_finger.STL" />
      </geometry>
      <material
        name="">
        <color
          rgba="0.3 0.3 0.3 1" />
      </material>
    </visual>
    <collision>
      <origin
        xyz="0 0 0"
        rpy="0 0 0" />
      <geometry>
        <mesh
          filename="package://wilson/collision_meshes/gripper_right_finger.STL" />
      </geometry>
    </collision>
  </link>
  <joint
    name="gripper_right_finger_joint"
    type="prismatic">
    <origin
      xyz="0.0272 0 0"
      rpy="0 0 0" />
    <parent
      link="gripper_base" />
    <child
      link="gripper_right_finger" />
    <axis
      xyz="0 0 1" />
    <limit
      lower="-0.05"
      upper="0.001"
      effort="0"
      velocity="0" />
  </joint>

</robot>